Workbook

Sheet README
B2: COMM/R & COEC 387 - Assignment 3 Solutions
B4: Contents
B5: P1 Venture Math | C5: Problem 1 (DubiousLedger): all calculations with live formulas. Blue cells are inputs - change them and every answer updates.
B6: Raincouver Model | C6: The original financial model provided with the assignment (unchanged).
B7: Raincouver Metrics | C7: Supporting calculations for Problem 2 (Raincouver AI): SaaS metrics built by formula from the model, benchmarks and ratings. The written answers (Q1-Q4) are in the separate Word file "Assignment3_Raincouver_AI_Answers.docx".
B9: Conventions
B10: Colour code | C10: Blue font = hard-coded input; black = formula; green fill = final answer; yellow fill = comment / assumption.
B11: Units | C11: Problem 1 in $ millions (founder shares in units). Raincouver model in $ thousands.
B12: Numbering note | C12: The assignment PDF contains Problem 1 (DubiousLedger) and Problem 2 (Raincouver AI). Raincouver AI is the problem built on the Excel model, and its written answers are delivered in a separate Word file, as the instructions require.

Sheet P1 Venture Math
B1: Problem 1 - DubiousLedger: how much can the founders raise and still keep 34%?
B3: Inputs | C3: Value | E3: Source / comment
B4: Exit value ($M) | C4: 100 | E4: Given: sale for $100M
B5: Years to exit | C5: 10 | E5: Given
B6: Founder shares today | C6: 1000000 | E6: Given: 1 million shares
B7: Founders' target ownership at exit | C7: 0.34 | E7: Given: keep 34% until exit
B8: VC target annual compound return | C8: 0.4 | E8: Given
B9: Round-2 amount ($M) | C9: 3 | E9: Q2: $3M raised from VCs ...
B10: Round-2 timing (years from today) | C10: 4 | E10: ... 4 years from now
B12: Method (explained)
B13: Key idea: a VC who invests $X today needs X*(1+r)^n at exit. If the exit is worth $100M, that sum is a fixed fraction of the company: required ownership = X*(1+r)^n / Exit value. Whatever the VCs must own, the founders keep the rest (1 - VC ownership). With several rounds, each investor's required share of the EXIT value is computed with the compounding that applies to ITS holding period, and the required shares simply add up (later-round dilution is already captured because ownership is defined at exit).
B15: Q1(a). Can DubiousLedger raise $4M in one round today and let founders keep >= 34%?
B16: Amount raised today ($M) | C16: 4
B17: VC required multiple over 10 years = (1+r)^n | C17: =(1+$C$8)^$C$5 -> 28.925465
B18: VC value required at exit ($M) = X * multiple | C18: =C16*C17 -> 115.70186
B19: VC ownership required at exit | C19: =C18/$C$4 -> 1.1570186 | E19: More than 100% -> the VCs would need more than the whole company: $4M x 28.9 = $115.7M > $100M exit.
B20: Founders' ownership at exit = 1 - VC ownership | C20: =1-C19 -> -0.15701862
B21: Feasible (founders >= 34%)? | C21: =IF(C20>=$C$7,"YES","NO") -> NO | E21: Not feasible: even at 100% VC ownership the $4M cannot earn 40%/yr on a $100M exit.
B23: Q1(b). Maximum raise today so that founders keep exactly 34%
B24: Maximum VC ownership at exit = 1 - 34% | C24: =1-$C$7 -> 0.66
B25: Maximum VC value at exit ($M) | C25: =C24*$C$4 -> 66
B26: MAXIMUM AMOUNT RAISED TODAY ($M) = value / multiple | C26: =C25/C17 -> 2.2817265 | E26: Calc: 0.66 x $100M / 1.4^10 = about $2.28M (so $4M is too much; ~$2.28M is the ceiling).
B27: Check: founders' ownership at exit with this raise | C27: =1-C26*C17/$C$4 -> 0.34
B28: Founders' shares / total shares post-round (shares check) | C28: =$C$6/$C$7 -> 2941176.5 | E28: Total shares needed so 1,000,000 founder shares = 34%
B29: New shares issued to VCs | C29: =C28-$C$6 -> 1941176.5
B30: Implied price per share today ($) | C30: =C26*1000000/C29 -> 1.1754348
B31: Implied pre-money / post-money valuation today ($M) | C31: =C30*$C$6/1000000 -> 1.1754348 | D31: =C30*C28/1000000 -> 3.4571613
B33: Q2. Two rounds: $3M raised 4 years from now; maximum raised today (founders keep 34%)
B34: Round-2 multiple over remaining years = (1+r)^(n - t2) | C34: =(1+$C$8)^($C$5-$C$10) -> 7.529536
B35: Round-2 investors' required value at exit ($M) | C35: =$C$9*C34 -> 22.588608
B36: Round-2 investors' ownership at exit | C36: =C35/$C$4 -> 0.22588608
B37: Max total VC ownership at exit = 1 - 34% | C37: =1-$C$7 -> 0.66
B38: Ownership left for round-1 (today) investors at exit | C38: =C37-C36 -> 0.43411392
B39: Round-1 investors' value at exit ($M) | C39: =C38*$C$4 -> 43.411392
B40: MAXIMUM RAISED TODAY ($M) = value / 1.4^10 | C40: =C39/C17 -> 1.5008018 | E40: Calc: (66% - 22.6%) x $100M / 1.4^10 = about $1.50M today, then $3M in year 4 (total $4.50M).
B41: Total capital raised across both rounds ($M) | C41: =C40+$C$9 -> 4.5008018 | E41: Staging raises ~$2.2M more in total than the single round ($2.28M) because year-4 money only has to compound 6 years, not 10.
B42: Check: founders' ownership at exit | C42: =1-C36-C40*C17/$C$4 -> 0.34
B43: Check: round-1 stake value at yr 4 ($M) = X*(1+r)^t2 | C43: =C40*(1+$C$8)^$C$10 -> 5.7654804
B44: Check: implied post-money at yr 4 ($M) = $3M / round-2 ownership | C44: =$C$9/C36 -> 13.281031
B45: Check: round-1 share of that post-money ($M) = own% x post-money | C45: =C38*C44 -> 5.7654804 | E45: Equals the previous check line -> the two rounds are internally consistent.
...

Sheet Raincouver Metrics
B1: Raincouver AI - SaaS metrics built from the model ($ thousands)
B2: All figures are formulas linked to the "Raincouver Model" sheet (annual columns F:I). Operating loss is used as a proxy for burn because the model has no cash-flow statement.
B4: Metric | C4: FY21A | D4: FY22E | E4: FY23E | F4: FY24E | H4: Benchmark (approx., see sources below) | I4: Rating FY24E vs benchmark
B5: Scale & growth
B6: Starting ARR | C6: ='Raincouver Model'!F10 -> 7911.99 | D6: ='Raincouver Model'!G10 -> 14531.931 | E6: ='Raincouver Model'!H10 -> 27819.299 | F6: ='Raincouver Model'!I10 -> 60158.278
B7: Ending ARR | C7: ='Raincouver Model'!F20 -> 14531.931 | D7: ='Raincouver Model'!G20 -> 27819.299 | E7: ='Raincouver Model'!H20 -> 60158.278 | F7: ='Raincouver Model'!I20 -> 111585.28
B8: ARR growth (YoY) | C8: ='Raincouver Model'!F20/'Raincouver Model'!F10-1 -> 0.83669734 | D8: ='Raincouver Model'!G20/'Raincouver Model'!G10-1 -> 0.9143567 | E8: ='Raincouver Model'!H20/'Raincouver Model'!H10-1 -> 1.1624656 | F8: ='Raincouver Model'!I20/'Raincouver Model'!I10-1 -> 0.85486156 | H8: Median ~35-50% at $10-100M ARR; top quartile 80-100%+ | I8: Top quartile
B9: Revenue | C9: ='Raincouver Model'!F25 -> 8512.6215 | D9: ='Raincouver Model'!G25 -> 16980.596 | E9: ='Raincouver Model'!H25 -> 35440.397 | F9: ='Raincouver Model'!I25 -> 70580.731
B10: Revenue growth (YoY) | D10: ='Raincouver Model'!G25/'Raincouver Model'!F25-1 -> 0.99475516 | E10: ='Raincouver Model'!H25/'Raincouver Model'!G25-1 -> 1.0871115 | F10: ='Raincouver Model'!I25/'Raincouver Model'!H25-1 -> 0.99153331 | H10: as above | I10: Top quartile
B12: Retention (dollar-based, annual, on starting ARR)
B13: Gross $ churn % of starting ARR | C13: =-'Raincouver Model'!F17/'Raincouver Model'!F10 -> 0.48406507 | D13: =-'Raincouver Model'!G17/'Raincouver Model'!G10 -> 0.28895772 | E13: =-'Raincouver Model'!H17/'Raincouver Model'!H10 -> 0.28724095 | F13: =-'Raincouver Model'!I17/'Raincouver Model'!I10 -> 0.2235935 | H13: Median ~10-15%; SMB-focused 20-30%+; enterprise <8% | I13: Bottom quartile
B14: Gross revenue retention (GRR) | C14: =1-C13 -> 0.51593493 | D14: =1-D13 -> 0.71104228 | E14: =1-E13 -> 0.71275905 | F14: =1-F13 -> 0.7764065 | H14: Median ~85-90%; top quartile >92% | I14: Bottom quartile
B15: Net revenue retention (NRR) | C15: =('Raincouver Model'!F10+'Raincouver Model'!F13+'Raincouver Model'!F14+'Raincouver Model'!F17)/'Raincouver Model'!F10 -> 0.99925278 | D15: =('Raincouver Model'!G10+'Raincouver Model'!G13+'Raincouver Model'!G14+'Raincouver Model'!G17)/'Raincouver Model'!G10 -> 1.174166 | E15: =('Raincouver Model'!H10+'Raincouver Model'!H13+'Raincouver Model'!H14+'Raincouver Model'!H17)/'Raincouver Model'!H10 -> 1.2922026 | F15: =('Raincouver Model'!I10+'Raincouver Model'!I13+'Raincouver Model'!I14+'Raincouver Model'!I17)/'Raincouver Model'!I10 -> 1.288223 | H15: Median ~100-105%; top quartile >120% | I15: Top quartile
B16: Upsell+expansion % of starting ARR | C16: =('Raincouver Model'!F13+'Raincouver Model'!F14)/'Raincouver Model'!F10 -> 0.48331785 | D16: =('Raincouver Model'!G13+'Raincouver Model'!G14)/'Raincouver Model'!G10 -> 0.46312372 | E16: =('Raincouver Model'!H13+'Raincouver Model'!H14)/'Raincouver Model'!H10 -> 0.57944352 | F16: =('Raincouver Model'!I13+'Raincouver Model'!I14)/'Raincouver Model'!I10 -> 0.51181651
B17: New-logo share of gross new ARR | C17: ='Raincouver Model'!F12/'Raincouver Model'!F15 -> 0.63406147 | D17: ='Raincouver Model'!G12/'Raincouver Model'!G15 -> 0.61512659 | E17: ='Raincouver Model'!H12/'Raincouver Model'!H15 -> 0.6003029 | F17: ='Raincouver Model'!I12/'Raincouver Model'!I15 -> 0.52541694
B19: Margins & cost structure (% of revenue)
B20: Gross margin | C20: ='Raincouver Model'!F29/'Raincouver Model'!F25 -> 0.64547181 | D20: ='Raincouver Model'!G29/'Raincouver Model'!G25 -> 0.68410755 | E20: ='Raincouver Model'!H29/'Raincouver Model'!H25 -> 0.73330051 | F20: ='Raincouver Model'!I29/'Raincouver Model'!I25 -> 0.75854391 | H20: Median ~75-78%; top quartile 80%+; AI-native often 50-65% | I20: Below median (lower-mid)
B21: S&M % of revenue | C21: =-'Raincouver Model'!F38/'Raincouver Model'!F25 -> 1.6690392 | D21: =-'Raincouver Model'!G38/'Raincouver Model'!G25 -> 1.5196761 | E21: =-'Raincouver Model'!H38/'Raincouver Model'!H25 -> 1.3017574 | F21: =-'Raincouver Model'!I38/'Raincouver Model'!I25 -> 0.9252334 | H21: Median ~35-45%; high-growth up to 50-60% | I21: Bottom quartile
B22: R&D % of revenue | C22: =-'Raincouver Model'!F41/'Raincouver Model'!F25 -> 0.98437533 | D22: =-'Raincouver Model'!G41/'Raincouver Model'!G25 -> 0.82822974 | E22: =-'Raincouver Model'!H41/'Raincouver Model'!H25 -> 0.6261615 | F22: =-'Raincouver Model'!I41/'Raincouver Model'!I25 -> 0.44308188 | H22: Median ~25-30% | I22: Bottom quartile (but falling fast)
B23: G&A % of revenue | C23: =-'Raincouver Model'!F44/'Raincouver Model'!F25 -> 0.3623009 | D23: =-'Raincouver Model'!G44/'Raincouver Model'!G25 -> 0.36523187 | E23: =-'Raincouver Model'!H44/'Raincouver Model'!H25 -> 0.22813696 | F23: =-'Raincouver Model'!I44/'Raincouver Model'!I25 -> 0.20754552 | H23: Median ~15-20% | I23: Bottom quartile / near median by FY24
B24: Operating margin | C24: ='Raincouver Model'!F50/'Raincouver Model'!F25 -> -2.3702436 | D24: ='Raincouver Model'!G50/'Raincouver Model'!G25 -> -2.0290301 | E24: ='Raincouver Model'!H50/'Raincouver Model'!H25 -> -1.4227554 | F24: ='Raincouver Model'!I50/'Raincouver Model'!I25 -> -0.81731689 | H24: Median ~ -20% to -30% for growth-stage SaaS | I24: Bottom quartile
B25: Rule of 40 (revenue growth + operating margin) | D25: =D10+D24 -> -1.034275 | E25: =E10+E24 -> -0.33564386 | F25: =F10+F24 -> 0.17421643 | H25: Median ~10-20%; top quartile >40% | I25: Below median (FY24 closest)
B27: Efficiency
B28: Operating loss (burn proxy) | C28: =-'Raincouver Model'!F50 -> 20176.987 | D28: =-'Raincouver Model'!G50 -> 34454.14 | E28: =-'Raincouver Model'!H50 -> 50423.015 | F28: =-'Raincouver Model'!I50 -> 57686.823
B29: Net new ARR | C29: ='Raincouver Model'!F18 -> 6619.941 | D29: ='Raincouver Model'!G18 -> 13287.368 | E29: ='Raincouver Model'!H18 -> 32338.979 | F29: ='Raincouver Model'!I18 -> 51427
B30: Burn multiple = burn / net new ARR | C30: =C28/C29 -> 3.0479103 | D30: =D28/D29 -> 2.5929995 | E30: =E28/E29 -> 1.5592024 | F30: =F28/F29 -> 1.1217225 | H30: <1x amazing, 1-1.5x great, 1.5-2x good, 2-3x suspect, >3x bad (Craft Ventures) | I30: Great by FY24 (1.1x); bad in FY21-22
B31: Sales efficiency = gross new ARR / S&M | C31: ='Raincouver Model'!F15/-'Raincouver Model'!F38 -> 0.73549644 | D31: ='Raincouver Model'!G15/-'Raincouver Model'!G38 -> 0.67763917 | E31: ='Raincouver Model'!H15/-'Raincouver Model'!H38 -> 0.87417354 | F31: ='Raincouver Model'!I15/-'Raincouver Model'!I38 -> 0.993482 | H31: Median ~0.7-0.8x; top quartile >1.0x | I31: Median / near top quartile
B32: CAC payback (months, gross-margin adjusted) | C32: =-'Raincouver Model'!F38/('Raincouver Model'!F15*C20)*12 -> 25.276876 | D32: =-'Raincouver Model'!G38/('Raincouver Model'!G15*D20)*12 -> 25.885607 | E32: =-'Raincouver Model'!H38/('Raincouver Model'!H15*E20)*12 -> 18.719817 | F32: =-'Raincouver Model'!I38/('Raincouver Model'!I15*F20)*12 -> 15.923573 | H32: Median ~20-24 mo; top quartile <12-15 mo | I32: Median improving to upper-mid
B35: Model observations / data-quality flags (comments)
B36: Revenue lags ARR: Q4-24 revenue x4 = ~$86M vs ending ARR $111.6M (about 30% gap). Ask whether ARR includes contracted-not-yet-live customers.
B37: Cell K21 divides Q1-21 ending ARR by a hard-coded 6,412 instead of the 7,912 starting ARR (K10) - inconsistent opening base; growth in Q1-21 is overstated.
B38: FY24 quarterly new-logo / upsell / expansion inputs are rounded hard-codes (e.g. 8,105; 8,374; 8,656; 8,953), unlike the formula-like FY22-23 numbers: looks like top-down targets, not a bottoms-up build.
B39: No customer counts, cohort data, ACV, cash balance or cash-flow: LTV/CAC, logo churn and runway cannot be computed - these are diligence requests.
B40: FY21A is actual; FY22E-FY24E are forecasts. Quarterly ARR growth decelerates from 38% (Q1-21) to 14% (Q4-24), while revenue growth stays ~100% YoY.
B41: Benchmarks are approximate medians/quartiles recalled from public SaaS surveys (see below), rounded to ranges; they should be re-checked against the latest edition before relying on them.
B43: Benchmark sources
B44: KeyBanc Capital Markets & Sapphire Ventures - Private SaaS Company Survey (growth, retention, CAC payback, cost structure by ARR band)
B45: OpenView Partners - SaaS Benchmarks Report (growth, NRR, GRR, gross margin, S&M efficiency)
B46: ICONIQ Growth - Topline Growth & Operational Efficiency report (growth, burn multiple, Rule of 40)
B47: Craft Ventures (David Sacks) - "The Burn Multiple" (burn / net new ARR thresholds)
...

Sheet Raincouver Model
B2: Summary P&L
B3: 2021 Planning
F5: FY2021A | G5: FY2022E | H5: FY2023E | I5: FY2024E | K5: FY2021A | O5: FY2022E | S5: FY2023E | W5: FY2024E
F6: FY21A | G6: FY22E | H6: FY23E | I6: FY24E | K6: Q1-21A | L6: Q2-21A | M6: Q3-21A | N6: Q4-21A | O6: Q1-22E | P6: Q2-22E | Q6: Q3-22E | R6: Q4-22E | S6: Q1-23E | T6: Q2-23E | U6: Q3-23E | V6: Q4-23E | W6: Q1-24E | X6: Q2-24E | Y6: Q3-24E | Z6: Q4-24E
A8: x | B8: ARR
B10: Starting ARR | F10: =K10 -> 7911.99 | G10: =F20 -> 14531.931 | H10: =G20 -> 27819.299 | I10: =H20 -> 60158.278 | K10: 7911.99 | L10: =K20 -> 8879.115 | M10: =L20 -> 9659.273 | N10: =M20 -> 11020.71 | O10: =N20 -> 14531.931 | P10: =O20 -> 16999.707 | Q10: =P20 -> 19727.816 | R10: =Q20 -> 23403.985 | S10: =R20 -> 27819.299 | ... Z10: =Y20 -> 97760.278
B12: (+) New Logo | F12: =SUM(K12:N12) -> 6625.853 | G12: =SUM(O12:R12) -> 10756.4 | H12: =SUM(S12:V12) -> 24210.108 | I12: =SUM(W12:Z12) -> 34088 | K12: 1111.923 | L12: 1117.658 | M12: 1859.579 | N12: 2536.693 | O12: 2215 | P12: 2231.1875 | Q12: 2871.75 | R12: 3438.4625 | S12: 4273.0833 | T12: 5534.175 | U12: 6758.475 | V12: 7644.375 | W12: 8105 | X12: 8374 | Y12: 8656 | Z12: 8953
B13: (+) Upsell | F13: =SUM(K13:N13) -> 2018.771 | G13: =SUM(O13:R13) -> 4136.0647 | H13: =SUM(S13:V13) -> 9874.6051 | I13: =SUM(W13:Z13) -> 16340 | K13: 246.343 | L13: 308.838 | M13: 370.216 | N13: 1093.374 | O13: 639.7276 | P13: 900.57967 | Q13: 1268.0562 | R13: 1327.7012 | S13: 1796.6876 | T13: 2066.2724 | U13: 2668.8604 | V13: 3342.7848 | W13: 3571 | X13: 4061 | Y13: 4370 | Z13: 4338
B14: (+) Expansion | F14: =SUM(K14:N14) -> 1805.235 | G14: =SUM(O14:R14) -> 2594.0173 | H14: =SUM(S14:V14) -> 6245.1075 | I14: =SUM(W14:Z14) -> 14450 | K14: 424.592 | L14: 302.602 | M14: 275.049 | N14: 802.992 | O14: 477.98843 | P14: 557.08826 | Q14: 627.59794 | R14: 931.34264 | S14: 1077.4361 | T14: 1363.744 | U14: 1776.1304 | V14: 2027.7971 | W14: 2783 | X14: 2959 | Y14: 4008 | Z14: 4700
B15: Gross New ARR | F15: =SUM(F12:F14) -> 10449.859 | G15: =SUM(G12:G14) -> 17486.482 | H15: =SUM(H12:H14) -> 40329.821 | I15: =SUM(I12:I14) -> 64878 | K15: =SUM(K12:K14) -> 1782.858 | L15: =SUM(L12:L14) -> 1729.098 | M15: =SUM(M12:M14) -> 2504.844 | N15: =SUM(N12:N14) -> 4433.059 | O15: =SUM(O12:O14) -> 3332.716 | P15: =SUM(P12:P14) -> 3688.8554 | Q15: =SUM(Q12:Q14) -> 4767.4042 | R15: =SUM(R12:R14) -> 5697.5064 | ... Z15: =SUM(Z12:Z14) -> 17991
B17: (-) Churn | F17: =SUM(K17:N17) -> -3829.918 | G17: =SUM(O17:R17) -> -4199.1136 | H17: =SUM(S17:V17) -> -7990.842 | I17: =SUM(W17:Z17) -> -13451 | K17: -815.733 | L17: -948.94 | M17: -1143.407 | N17: -921.838 | O17: -864.93976 | P17: -960.74675 | Q17: -1091.2351 | R17: -1282.1919 | S17: -1659.4723 | T17: -1774.394 | U17: -2099.2986 | V17: -2457.6771 | W17: -2707 | X17: -2988 | Y17: -3590 | Z17: -4166
B18: Net New ARR | F18: =F17+F15 -> 6619.941 | G18: =G17+G15 -> 13287.368 | H18: =H17+H15 -> 32338.979 | I18: =I17+I15 -> 51427 | K18: =K17+K15 -> 967.125 | L18: =L17+L15 -> 780.158 | M18: =M17+M15 -> 1361.437 | N18: =N17+N15 -> 3511.221 | O18: =O17+O15 -> 2467.7763 | P18: =P17+P15 -> 2728.1087 | Q18: =Q17+Q15 -> 3676.169 | R18: =R17+R15 -> 4415.3144 | ... Z18: =Z17+Z15 -> 13825
B20: Ending ARR | F20: =F18+F10 -> 14531.931 | G20: =G18+G10 -> 27819.299 | H20: =H18+H10 -> 60158.278 | I20: =I18+I10 -> 111585.28 | K20: =K18+K10 -> 8879.115 | L20: =L18+L10 -> 9659.273 | M20: =M18+M10 -> 11020.71 | N20: =N18+N10 -> 14531.931 | O20: =O18+O10 -> 16999.707 | P20: =P18+P10 -> 19727.816 | Q20: =Q18+Q10 -> 23403.985 | R20: =R18+R10 -> 27819.299 | ... Z20: =Z18+Z10 -> 111585.28
B21: % growth | F21: =F20/(F10)-1 -> 0.83669734 | G21: =G20/F20-1 -> 0.9143567 | H21: =H20/G20-1 -> 1.1624656 | I21: =I20/H20-1 -> 0.85486156 | K21: =K20/(6412)-1 -> 0.38476528 | L21: =L20/K20-1 -> 0.087864387 | M21: =M20/L20-1 -> 0.14094611 | N21: =N20/M20-1 -> 0.31860207 | O21: =O20/N20-1 -> 0.16981751 | P21: =P20/O20-1 -> 0.16047974 | Q21: =Q20/P20-1 -> 0.18634445 | R21: =R20/Q20-1 -> 0.18865652 | S21: =S20/R20-1 -> 0.19726358 | ... Z21: =Z20/Y20-1 -> 0.14141736
A23: x | B23: P&L
B25: Revenue | F25: =SUM(K25:N25) -> 8512.6215 | G25: =SUM(O25:R25) -> 16980.596 | H25: =SUM(S25:V25) -> 35440.397 | I25: =SUM(W25:Z25) -> 70580.731 | K25: 1714.284 | L25: 1864.9085 | M25: 2127.7601 | N25: 2805.6689 | O25: 3282.1206 | P25: 3808.8345 | Q25: 4518.5896 | R25: 5371.051 | S25: 6430.5638 | T25: 7818.6925 | U25: 9576.4272 | V25: 11614.713 | W25: 13883.663 | X25: 16278.88 | Y25: 18874.503 | Z25: 21543.685
B26: % growth | G26: =G25/F25-1 -> 0.99475516 | H26: =H25/G25-1 -> 1.0871115 | I26: =I25/H25-1 -> 0.99153331 | L26: =L25/K25-1 -> 0.087864387 | M26: =M25/L25-1 -> 0.14094611 | N26: =N25/M25-1 -> 0.31860207 | O26: =O25/N25-1 -> 0.16981751 | P26: =P25/O25-1 -> 0.16047974 | Q26: =Q25/P25-1 -> 0.18634445 | R26: =R25/Q25-1 -> 0.18865652 | S26: =S25/R25-1 -> 0.19726358 | ... Z26: =Z25/Y25-1 -> 0.14141736
B28: (-) COS | F28: =SUM(K28:N28) -> -3017.9643 | G28: =SUM(O28:R28) -> -5364.042 | H28: =SUM(S28:V28) -> -9451.9356 | I28: =SUM(W28:Z28) -> -17042.147 | K28: -667.60312 | L28: -687.19234 | M28: -745.45578 | N28: -917.71308 | O28: -1112.718 | P28: -1262.8235 | Q28: -1425.3238 | R28: -1563.1767 | S28: -1864.7217 | T28: -2186.6237 | U28: -2519.275 | V28: -2881.3152 | W28: -3357.7381 | X28: -3942.0514 | Y28: -4556.1507 | Z28: -5186.2069
B29: Gross Profit | F29: =F28+F25 -> 5494.6572 | G29: =G28+G25 -> 11616.554 | H29: =H28+H25 -> 25988.461 | I29: =I28+I25 -> 53538.584 | K29: =K28+K25 -> 1046.6809 | L29: =L28+L25 -> 1177.7162 | M29: =M28+M25 -> 1382.3043 | N29: =N28+N25 -> 1887.9558 | O29: =O28+O25 -> 2169.4026 | P29: =P28+P25 -> 2546.011 | Q29: =Q28+Q25 -> 3093.2659 | R29: =R28+R25 -> 3807.8744 | ... Z29: =Z28+Z25 -> 16357.478
B30: % margin | F30: =F29/F$25 -> 0.64547181 | G30: =G29/G$25 -> 0.68410755 | H30: =H29/H$25 -> 0.73330051 | I30: =I29/I$25 -> 0.75854391 | K30: =K29/K$25 -> 0.61056446 | L30: =L29/L$25 -> 0.63151418 | M30: =M29/M$25 -> 0.64965234 | N30: =N29/N$25 -> 0.67290756 | O30: =O29/O$25 -> 0.66097589 | P30: =P29/P$25 -> 0.66844883 | Q30: =Q29/Q$25 -> 0.68456446 | R30: =R29/R$25 -> 0.70896261 | ... Z30: =Z29/Z$25 -> 0.7592702
B32: Sales | F32: =SUM(K32:N32) -> -9963.2617 | G32: =SUM(O32:R32) -> -19304.683 | H32: =SUM(S32:V32) -> -35712.592 | I32: =SUM(W32:Z32) -> -51824.005 | K32: -2300.8268 | L32: -1968.7139 | M32: -2396.0657 | N32: -3297.6553 | O32: -3335.0378 | P32: -4504.388 | Q32: -5604.0513 | R32: -5861.2061 | S32: -7862.3075 | T32: -8316.5767 | U32: -9726.8447 | V32: -9806.8632 | W32: -10889.118 | X32: -12238.698 | Y32: -13746.424 | Z32: -14949.764
B33: % margin | F33: =(F32/F$25) -> -1.1704105 | G33: =(G32/G$25) -> -1.1368672 | H33: =(H32/H$25) -> -1.0076804 | I33: =(I32/I$25) -> -0.73425147 | K33: =(K32/K$25) -> -1.3421503 | L33: =(L32/L$25) -> -1.0556625 | M33: =(M32/M$25) -> -1.1260977 | N33: =(N32/N$25) -> -1.1753544 | O33: =(O32/O$25) -> -1.0161229 | P33: =(P32/P$25) -> -1.1826158 | Q33: =(Q32/Q$25) -> -1.2402213 | R33: =(R32/R$25) -> -1.0912587 | ... Z33: =(Z32/Z$25) -> -0.69392791
B35: Marketing | F35: =SUM(K35:N35) -> -4244.6371 | G35: =SUM(O35:R35) -> -6500.3216 | H35: =SUM(S35:V35) -> -10422.207 | I35: =SUM(W35:Z35) -> -13479.644 | K35: -1076.1188 | L35: -1154.1801 | M35: -923.10103 | N35: -1091.2371 | O35: -1249.1356 | P35: -1717.5288 | Q35: -1708.8452 | R35: -1824.8119 | S35: -2065.4952 | T35: -2716.9274 | U35: -2706.6318 | V35: -2933.1529 | W35: -2701.8023 | X35: -3138.9369 | Y35: -3591.3507 | Z35: -4047.5542
B36: % margin | F36: =(F35/F$25) -> -0.49862866 | G36: =(G35/G$25) -> -0.38280881 | H36: =(H35/H$25) -> -0.29407705 | I36: =(I35/I$25) -> -0.19098193 | K36: =(K35/K$25) -> -0.62773661 | L36: =(L35/L$25) -> -0.61889369 | M36: =(M35/M$25) -> -0.43383698 | N36: =(N35/N$25) -> -0.38894008 | O36: =(O35/O$25) -> -0.38058798 | P36: =(P35/P$25) -> -0.45093292 | Q36: =(Q35/Q$25) -> -0.37818111 | R36: =(R35/R$25) -> -0.3397495 | ... Z36: =(Z35/Z$25) -> -0.18787659
B38: Total S&M | F38: =F35+F32 -> -14207.899 | G38: =G35+G32 -> -25805.005 | H38: =H35+H32 -> -46134.799 | I38: =I35+I32 -> -65303.649 | K38: =K35+K32 -> -3376.9456 | L38: =L35+L32 -> -3122.894 | M38: =M35+M32 -> -3319.1667 | N38: =N35+N32 -> -4388.8924 | O38: =O35+O32 -> -4584.1734 | P38: =P35+P32 -> -6221.9168 | Q38: =Q35+Q32 -> -7312.8965 | R38: =R35+R32 -> -7686.018 | ... Z38: =Z35+Z32 -> -18997.318
B39: % margin | F39: =(F38/F$25) -> -1.6690392 | G39: =(G38/G$25) -> -1.5196761 | H39: =(H38/H$25) -> -1.3017574 | I39: =(I38/I$25) -> -0.9252334 | K39: =(K38/K$25) -> -1.9698869 | L39: =(L38/L$25) -> -1.6745562 | M39: =(M38/M$25) -> -1.5599347 | N39: =(N38/N$25) -> -1.5642945 | O39: =(O38/O$25) -> -1.3967108 | P39: =(P38/P$25) -> -1.6335488 | Q39: =(Q38/Q$25) -> -1.6184024 | R39: =(R38/R$25) -> -1.4310082 | ... Z39: =(Z38/Z$25) -> -0.8818045
B41: R&D | F41: =SUM(K41:N41) -> -8379.6146 | G41: =SUM(O41:R41) -> -14063.834 | H41: =SUM(S41:V41) -> -22191.412 | I41: =SUM(W41:Z41) -> -31273.043 | K41: -2038.5408 | L41: -2110.7908 | M41: -2046.7511 | N41: -2183.5319 | O41: -2418.4227 | P41: -3377.191 | Q41: -3890.9404 | R41: -4377.2803 | S41: -5013.661 | T41: -5506.001 | U41: -5653.5952 | V41: -6018.1548 | W41: -6705.5119 | X41: -7495.4372 | Y41: -8222.1219 | Z41: -8849.9722
B42: % margin | F42: =(F41/F$25) -> -0.98437533 | G42: =(G41/G$25) -> -0.82822974 | H42: =(H41/H$25) -> -0.6261615 | I42: =(I41/I$25) -> -0.44308188 | K42: =(K41/K$25) -> -1.18915 | L42: =(L41/L$25) -> -1.1318469 | M42: =(M41/M$25) -> -0.96192754 | N42: =(N41/N$25) -> -0.77825716 | O42: =(O41/O$25) -> -0.73684759 | P42: =(P41/P$25) -> -0.88667309 | Q42: =(Q41/Q$25) -> -0.86109621 | R42: =(R41/R$25) -> -0.81497649 | ... Z42: =(Z41/Z$25) -> -0.41079194
B44: G&A | F44: =SUM(K44:N44) -> -3084.1304 | G44: =SUM(O44:R44) -> -6201.8548 | H44: =SUM(S44:V44) -> -8085.2644 | I44: =SUM(W44:Z44) -> -14648.714 | K44: -659.15727 | L44: -741.2412 | M44: -799.55827 | N44: -884.1737 | O44: -1299.9593 | P44: -1680.8614 | Q44: -1672.2924 | R44: -1548.7417 | S44: -1831.3391 | T44: -2068.2337 | U44: -2082.9132 | V44: -2102.7784 | W44: -2835.8358 | X44: -3363.3855 | Y44: -3928.6338 | Z44: -4520.8592
B45: % margin | F45: =(F44/F$25) -> -0.3623009 | G45: =(G44/G$25) -> -0.36523187 | H45: =(H44/H$25) -> -0.22813696 | I45: =(I44/I$25) -> -0.20754552 | K45: =(K44/K$25) -> -0.38450879 | L45: =(L44/L$25) -> -0.39746786 | M45: =(M44/M$25) -> -0.37577463 | N45: =(N44/N$25) -> -0.31513829 | O45: =(O44/O$25) -> -0.39607298 | P45: =(P44/P$25) -> -0.44130597 | Q45: =(Q44/Q$25) -> -0.37009168 | R45: =(R44/R$25) -> -0.28834984 | ... Z45: =(Z44/Z$25) -> -0.20984614
B47: Total Opex | F47: =F44+F41+F38 -> -25671.644 | G47: =G44+G41+G38 -> -46070.694 | H47: =H44+H41+H38 -> -76411.476 | I47: =I44+I41+I38 -> -111225.41 | K47: =K44+K41+K38 -> -6074.6437 | L47: =L44+L41+L38 -> -5974.9261 | M47: =M44+M41+M38 -> -6165.4761 | N47: =N44+N41+N38 -> -7456.598 | O47: =O44+O41+O38 -> -8302.5554 | P47: =P44+P41+P38 -> -11279.969 | Q47: =Q44+Q41+Q38 -> -12876.129 | R47: =R44+R41+R38 -> -13612.04 | ... Z47: =Z44+Z41+Z38 -> -32368.15
B48: % margin | F48: =(F47/F$25) -> -3.0157154 | G48: =(G47/G$25) -> -2.7131377 | H48: =(H47/H$25) -> -2.1560559 | I48: =(I47/I$25) -> -1.5758608 | K48: =(K47/K$25) -> -3.5435457 | L48: =(L47/L$25) -> -3.2038709 | M48: =(M47/M$25) -> -2.8976368 | N48: =(N47/N$25) -> -2.6576899 | O48: =(O47/O$25) -> -2.5296314 | P48: =(P47/P$25) -> -2.9615278 | Q48: =(Q47/Q$25) -> -2.8495903 | R48: =(R47/R$25) -> -2.5343345 | ... Z48: =(Z47/Z$25) -> -1.5024426
B50: Operating Profit | F50: =F47+F29 -> -20176.987 | G50: =G47+G29 -> -34454.14 | H50: =H47+H29 -> -50423.015 | I50: =I47+I29 -> -57686.823 | K50: =K47+K29 -> -5027.9629 | L50: =L47+L29 -> -4797.2099 | M50: =M47+M29 -> -4783.1717 | N50: =N47+N29 -> -5568.6421 | O50: =O47+O29 -> -6133.1528 | P50: =P47+P29 -> -8733.9583 | Q50: =Q47+Q29 -> -9782.8635 | R50: =R47+R29 -> -9804.1657 | ... Z50: =Z47+Z29 -> -16010.672
B51: % margin | F51: =(F50/F$25) -> -2.3702436 | G51: =(G50/G$25) -> -2.0290301 | H51: =(H50/H$25) -> -1.4227554 | I51: =(I50/I$25) -> -0.81731689 | K51: =(K50/K$25) -> -2.9329813 | L51: =(L50/L$25) -> -2.5723567 | M51: =(M50/M$25) -> -2.2479845 | N51: =(N50/N$25) -> -1.9847824 | O51: =(O50/O$25) -> -1.8686555 | P51: =(P50/P$25) -> -2.293079 | Q51: =(Q50/Q$25) -> -2.1650259 | R51: =(R50/R$25) -> -1.8253719 | ... Z51: =(Z50/Z$25) -> -0.74317238
